const {HttpException} = require("../core/http-exception")
const catchError = async (ctx, next) => {
  try {
    ctx.set("Access-Control-Allow-Origin", "*");
    ctx.set("Access-Control-Allow-Methods", "OPTIONS, GET, PUT, POST, DELETE");
    ctx.set("Access-Control-Allow-Headers", "x-requested-with, accept, origin, content-type");
    ctx.set("Content-Type", "application/json;charset=utf-8");
    ctx.set("Access-Control-Allow-Credentials", true);
    ctx.set("Access-Control-Max-Age", 300);
    ctx.set("Access-Control-Expose-Headers", "myData");
    await next()
  } catch (error) {
    const isHttpException = error instanceof HttpException

    const isDev = global.config.environment === "dev"
    if (isDev && !isHttpException) {
      throw error;
    }

    if (isHttpException) {
      ctx.body = {
        msg: error.msg,
        errorCode: error.errorCode,
        request: `${ctx.method} ${ctx.path}`
      }
      ctx.status = error.code
    } else {
      ctx.body = {
        msg: 'we made a mistake (*^â–½^*)',
        errorCode: 999,
        request: `${ctx.method} ${ctx.path}`
      }
      ctx.status = 500
    }
  }
}

module.exports = catchError
